2025-09-13 18:04:57,015 - __main__ - INFO - Logging to logs\random_forest_training_20250913_180457.log
2025-09-13 18:04:57,015 - __main__ - INFO - Random Forest Training Pipeline initialized
2025-09-13 18:04:57,015 - __main__ - INFO - ==================================================
2025-09-13 18:04:57,016 - __main__ - INFO - STARTING RANDOM FOREST TRAINING PIPELINE
2025-09-13 18:04:57,016 - __main__ - INFO - ==================================================
2025-09-13 18:04:57,016 - __main__ - INFO - Loading data from Project_3\dataset\combined_dataset_short_balanced_encoded_normalised.csv
2025-09-13 18:04:57,478 - __main__ - INFO - Data loaded successfully: (500000, 15)
2025-09-13 18:04:57,479 - __main__ - ERROR - Training pipeline failed: 'RandomForestConfig' object has no attribute 'target_column'
Traceback (most recent call last):
  File "C:\Users\dicla\Research_Internship_Under_Dr_Rakesh_Matam\Project_3\RandomForestClassifier\scripts\train.py", line 509, in run_training
    data = self.load_and_validate_data(data_path)
  File "C:\Users\dicla\Research_Internship_Under_Dr_Rakesh_Matam\Project_3\RandomForestClassifier\scripts\train.py", line 217, in load_and_validate_data
    if self.config.target_column not in data.columns:
       ^^^^^^^^^^^^^^^^^^^^^^^^^
  File "C:\Users\dicla\Miniconda3\Lib\site-packages\pydantic\main.py", line 991, in __getattr__
    raise AttributeError(f'{type(self).__name__!r} object has no attribute {item!r}')
AttributeError: 'RandomForestConfig' object has no attribute 'target_column'
2025-09-13 18:04:57,483 - __main__ - ERROR - Training failed: 'RandomForestConfig' object has no attribute 'target_column'
Traceback (most recent call last):
  File "C:\Users\dicla\Research_Internship_Under_Dr_Rakesh_Matam\Project_3\RandomForestClassifier\scripts\train.py", line 567, in main
    results = pipeline.run_training(args.data)
  File "C:\Users\dicla\Research_Internship_Under_Dr_Rakesh_Matam\Project_3\RandomForestClassifier\scripts\train.py", line 509, in run_training
    data = self.load_and_validate_data(data_path)
  File "C:\Users\dicla\Research_Internship_Under_Dr_Rakesh_Matam\Project_3\RandomForestClassifier\scripts\train.py", line 217, in load_and_validate_data
    if self.config.target_column not in data.columns:
       ^^^^^^^^^^^^^^^^^^^^^^^^^
  File "C:\Users\dicla\Miniconda3\Lib\site-packages\pydantic\main.py", line 991, in __getattr__
    raise AttributeError(f'{type(self).__name__!r} object has no attribute {item!r}')
AttributeError: 'RandomForestConfig' object has no attribute 'target_column'
